Workbook

Sheet Q de registros
A3: Etiquetas de fila | B3: Cuenta de Tarea / Contexto
A4: ago | B4: 19
A5: 11-ago | B5: 1
A6: 14-ago | B6: 1
A7: 18-ago | B7: 1
A8: 20-ago | B8: 1
A9: 21-ago | B9: 3
A10: 25-ago | B10: 5
A11: 26-ago | B11: 2
A12: 27-ago | B12: 3
A13: 28-ago | B13: 1
A14: 31-ago | B14: 1
A15: sept | B15: 22
... A22: Total general | B22: 41

Sheet Q x colaborador
A3: Etiquetas de fila | B3: Cuenta de Tarea / Contexto
A4: Dennisse Cannobbio | B4: 7
A5: Jerson Pacheco | B5: 1
A6: Manuel Zamorano | B6: 1
A7: Moises Lagos | B7: 15
A8: Sergio Galaz | B8: 17
A9: Total general | B9: 41

Sheet Registro Diario
A1: Fecha | B1: Colaborador | C1: Rol | D1: Equipo | E1: Tarea / Contexto | F1: Herramienta IA | G1: Modelo | H1: Nivel de razonamiento | I1: MCP | J1: Tipo de uso | K1: Tokens consumidos | L1: Tiempo invertido (min) | M1: Tiempo estimado ahorrado (min) | N1: Resultado | O1: Confianza en el output (1-5) | P1: ¿Requirió validación humana? | Q1: Descripción | R1: Problemas encontrados | S1: Aprendizajes / Insights | T1: Riesgo identificado | U1: Sugerencias de mejora | V1: Etiquetas
A2: 46113 | B2: Sergio Galaz | C2: LT | D2: Ecosistemas | E2: Desarrollo | F2: GitHub Copilot Agent Skills | H2: Medio | I2: No aplica | J2: Generación de código | K2: 80% de la sesion | Q2: Se refactorizo componentes de angular para proyecto backoffice cupones | R2: Ninguno | S2: Ninguno | T2: Ninguno | U2: Ninguno | V2: Generación de código
A3: 46161 | B3: Moises Lagos | C3: DEV | D3: Ecosistemas | E3: Desarrollo | F3: Google Antigravity | G3: Gemini pro 3.1 | H3: Alto | I3: No aplica | J3: Generación de código | K3: 0 | L3: 2400 | M3: 1440 | N3: Parcial | O3: 3 | P3: Sí | Q3: Optimizaciones para apitrazabilidad. Netamente para abordar estos caso, se realizó de manera manual y a la vez, copiando y pegando código en chat de gemini web. La tarea tomó una semana y se estima que se ahorró 3 días de desarrollo. | R3: Resultados carentes de precisión. | S3: Utilizar el chat web proporcionando archivos directamente en el chat del navegador entrega resultados imprecisos y poco óptimos. No se ahorra tanto tiempo mediante este método y agota rápidamente la cuota de tokens. | T3: Calidad o precisión | U3: Usar entorno de desarrollo agéntico para desarrollar en conjunto con IA. | V3: Generación de código
A4: 46199 | B4: Moises Lagos | C4: DEV | D4: App & Ecosistemas | E4: Desarrollo | F4: Google Antigravity | G4: Gemini pro 3.1 | H4: Alto | I4: No aplica | J4: Generación de código | K4: 0 | L4: 1440 | M4: 960 | N4: Parcial | O4: 4 | P4: Sí | Q4: Desarrollo fullstack para funcionalidad de notificaciones para cupones. Se desarrollo de forma híbrida, vibecoding, copiando y pegando código a través de gemini web y de manera manual. Tarea de tamaño XL que se redujo a 4 días. | R4: De manera parcial el desarrollo fue asistido por IA, a prueba y error, por lo que en ocasiones el resultado no fue preciso, de la misma forma se iteró varias veces. | S4: Para este caso fue necesario un desarrollo guiado para usar la IA. | T4: Calidad o precisión | U4: Utilizar metodología para el uso de herramientas IA. Reducir vicoding, no realizar desarrollo parcial de manera manual. | V4: Generación de código
A5: 46237 | B5: Dennisse Cannobbio | C5: DEV | D5: Ecosistemas | E5: Otro | F5: Claude (chat web) | G5: Sonnet 5, plan Pro | H5: Alto | I5: No aplica | J5: Documentación técnica | K5: 5 % de la sesion | L5: 60 | M5: 0 | N5: Exito | O5: 5 | P5: Si | Q5: Investigacion a alto nivel sobre Spec Driven Development, frameworks de implementacion (openspec, spec pulse, github spec kit) | R5: Ninguno | S5: Ninguno | T5: Ninguno | U5: Ninguno | V5: Investigacion
A6: 46245 | B6: Sergio Galaz | C6: LT | D6: Ecosistemas | E6: Análisis | F6: Claude Code / GitHub Copilot Chat | G6: Claude 3.5 Sonnet | H6: Alto | I6: No aplica | J6: Documentación técnica | K6: 45 | L6: 120 | M6: 480 | N6: Éxito | O6: 5 | P6: Sí | Q6: Spec-Kit requiere un overhead de diseño inicial extremo y acoplamiento alto. Superpowers es demasiado invasivo en cambios visuales o ajustes menores. | R6: Elegimos OpenSpec por su naturaleza abierta, modular y su enfoque brownfield-first que permite documentar solo las "Delta Specs" de lo que vamos a modificar, sin "hervir el océano" de golpe. | S6: Resistencia inicial de la célula ante un flujo formal que requiere escribir propuesta, diseño y especificación antes de codificar. | T6: Adaptar OpenSpec de forma incremental en el equipo, empezando por HU de tamaño medio. | U6: SDD, OpenSpec, Spec-Kit, Superpowers, Benchmarking | V6: Informes, Presentación, Uso de patrones
A7: 46246 | B7: Moises Lagos | C7: DEV | D7: App & Ecosistemas | E7: Desarrollo | F7: Google Antigravity | G7: Gemini pro 3.1 | H7: Alto | I7: No aplica | J7: Generación de código | K7: 0 | L7: 960 | M7: 240 | N7: Parcial | O7: 3 | P7: Sí | Q7: Diseño en frontend para pantalla de listado de notificación.Tarea de 2.5 días se realizó en 2 días. Se desarrolló a modo de vibecoding y desarrollo parcial mediante chat de gemini web. | R7: Resultados poco precisos, se enviaron capturas de figma a antigravity y chat de gemini web. En las primeras iteraciones, los resultados fueron parciales, para resolver estilos, se hizo mediante vibecoding y de manera manual. | S7: Estructurar de mejor forma las especificaciones para maquetado. | T7: Calidad o precisión | U7: Utilizar metodología para el uso de herramientas IA. Reducir vicoding, no realizar desarrollo parcial de manera manual. | V7: Generación de código
A8: 46248 | B8: Luis Martinez | C8: DEV | D8: Ecosistemas | E8: Análisis | F8: Microsoft Copilot | G8: Claude Sonnet 5 | H8: Medio | I8: No aplica | J8: Análisis de requerimientos | K8: 10% de la session | L8: 1620 | M8: 1620 | N8: Parcial | O8: 5 | P8: Sí | Q8: Se solicito analisis de tarea en el cual se solicita un refactor de encolamiento de trazabilidades | R8: Ninguno | S8: Manejo de comando explorer del modelo para enviar prompt | T8: Ninguno | U8: Ninguno | V8: Exploracion de codigo y analisis
A9: 46248 | B9: Moises Lagos | C9: DEV | D9: App & Ecosistemas | E9: Desarrollo | F9: Google Antigravity | G9: Gemini pro 3.1 | H9: Alto | I9: No aplica | J9: Generación de código | K9: 0 | L9: 40 | M9: 240 | N9: Éxito | O9: 5 | P9: No | Q9: Implementación de funcionalidad de buscador de periodo en listado de notificación. Tarea fullstack. Se realizó de manera híbrida, mediante vibecoding y manual. | R9: Ninguno | S9: Ninguno | T9: Ninguno | U9: Usar entorno de desarrollo agéntico para desarrollar en conjunto con IA. | V9: Generación de código
A10: 46248 | B10: Moises Lagos | C10: DEV | D10: App & Ecosistemas | E10: Desarrollo | F10: Google Antigravity | G10: Gemini 3.8 flash | H10: Alto | I10: No aplica | J10: Generación de código | K10: 33% de la sesión | L10: 80 | M10: 480 | N10: Éxito | O10: 5 | P10: No | Q10: Implementación de auditoría y logging en backend. | R10: Ninguno | S10: Ninguno | T10: Ninguno | U10: Ninguno | V10: Generación de código
A11: 46249 | B11: Moises Lagos | C11: DEV | D11: App & Ecosistemas | E11: Análisis | F11: GitHub Copilot Agent Skills | G11: GPT 5.6 Terra | H11: Alto | I11: No aplica | J11: Análisis de requerimientos | K11: 334.5 | L11: 40 | M11: 120 | N11: Éxito | O11: 5 | P11: No | Q11: Planificación y especificación de refactor para manejo de fechas en UTC | R11: Ninguno | S11: Ninguno | T11: Ninguno | U11: Ninguno | V11: Analisis de requerimientos
A12: 46249 | B12: Moises Lagos | C12: DEV | D12: App & Ecosistemas | E12: Desarrollo | F12: Google Antigravity | G12: Gemini 3.8 flash | H12: Alto | I12: No aplica | J12: Generación de código | K12: 37% de la sesión | L12: 60 | M12: 240 | N12: Éxito | O12: 5 | P12: No | Q12: Implementación de código para refactor de fecha UCT | R12: Se demoró más de lo normal la generación de código, aunque la implementación fue correcta. Causa sin determinar | S12: Ninguno | T12: Ninguno | U12: Ninguno | V12: Generación de código
A13: 46250 | B13: Moises Lagos | C13: DEV | D13: App & Ecosistemas | E13: Desarrollo | F13: Google Antigravity | G13: Gemini 3.8 flash | H13: Alto | I13: No aplica | J13: Generación de código | K13: 30% de la sesion | L13: 40 | M13: 240 | N13: Éxito | O13: 4 | P13: Sí | Q13: Implementación de conversión de fecha UTC a hora local en frontend. | R13: Para las notificaciones con estado "Enviada", no formateo correctamente la hora(AM/PM) | S13: Ninguno | T13: Calidad o precisión | U13: Especificar al detalle. | V13: Generación de código
A14: 46250 | B14: Moises Lagos | C14: DEV | D14: App & Ecosistemas | E14: Desarrollo | F14: GitHub Copilot Agent Skills | G14: GPT 5.6 Terra | H14: Alto | I14: No aplica | J14: Refactor | K14: 306.2 | L14: 50 | M14: 240 | N14: Éxito | O14: 5 | P14: No | Q14: Análisis para refactorizar procesamiento de carga push, mejorando transacciones y consultas a base de datos, y mejorando tiempos de carga. | R14: Ninguno | S14: Ninguno | T14: Ninguno | U14: Ninguno | V14: Analisis de requerimientos
A15: 46251 | B15: Moises Lagos | C15: DEV | D15: App & Ecosistemas | E15: Desarrollo | F15: Google Antigravity | G15: Gemini 3.8 flash | H15: Alto | I15: No aplica | J15: Generación de código | K15: 25% de la sesión | L15: 60 | M15: 300 | N15: Éxito | O15: 5 | P15: No | Q15: Implementación refactorización procesamiento de carga. Originalmente, con 50000 registros la carga demoraba 40 minutos, con la nueva optimización tomó 29 minutos. | R15: Ninguno | S15: Ninguno | T15: Ninguno | U15: Ninguno | V15: Generación de código
A16: 46252 | B16: Sergio Galaz | C16: LT | D16: App & Ecosistemas | E16: Documentación | F16: Claude Code | G16: Claude 3.5 Sonnet | H16: Alto | I16: No aplica | J16: Documentación técnica | K16: 80 | L16: 90 | M16: 360 | N16: Éxito | O16: 5 | P16: Sí | Q16: El equipo técnico no tiene claro cómo interactuar con los comandos /opsx: dentro del chat de la IA frente a la consola. | R16: Se definió claramente que los comandos /opsx:propose, /opsx:apply y /opsx:archive se ejecutan exclusivamente en la interfaz de chat del asistente, mientras que openspec init corre en la terminal física de la laptop. | S16: Confusión en los comandos locales de la terminal vs comandos de chat de la IA. | T16: Crear un manual ilustrativo rápido para el onboarding de nuevos desarrolladores. | U16: SDD, OpenSpec, Onboarding, Procesos | V16: Informes, Presentación, Uso de patrones
A17: 46253 | B17: Moises Lagos | C17: DEV | D17: App & Ecosistemas | E17: Desarrollo | F17: GitHub Copilot Chat | G17: GPT 5.6 Terra | H17: Medio | I17: No aplica | J17: Generación de código | K17: 0 | L17: 30 | M17: 240 | N17: Éxito | O17: 5 | P17: No | Q17: Implementación de paginación para listado de notificaciones en backend. Se utilizó el chat integrado de visual studio insiders con copilot en modalidad vibecoding. | R17: Ninguno | S17: Ninguno | T17: Ninguno | U17: Reducir vibecoding. | V17: Generación de código
A18: 46253 | B18: Moises Lagos | C18: DEV | D18: App & Ecosistemas | E18: Desarrollo | F18: Google Antigravity | G18: Gemini pro 3.1 | H18: Alto | I18: No aplica | J18: Generación de código | K18: 0 | L18: 40 | M18: 240 | N18: Parcial | O18: 4 | P18: Sí | Q18: Implementación de funcionalidad para listado de notificación, integrando servicios backend en frontend. Se desarrolla en modalidad vibecoding. | R18: Resultados con impresiciones. Se tuvo que iterar más de una vez en modalidad vibecoding para refinar resultados. | S18: Procurar especificar requerimientos técnicos para mejorar resultados generados. | T18: Calidad o precisión | U18: Reducir vibecoding, mejorar especificación. | V18: Generación de código
A19: 46254 | B19: Moises Lagos | C19: DEV | D19: App & Ecosistemas | E19: Desarrollo | F19: GitHub Copilot Agent Skills | G19: GPT 5.6 Terra | H19: Medio | I19: No aplica | J19: Generación de código | K19: 0 | L19: 10 | M19: 120 | N19: Éxito | O19: 5 | P19: No | Q19: Endpoint para reporte. En ese momento no se utilizaba openspec para el desarrollo guiado. Se abordó con análisis y generación de código a la vez mediante vibecoding | R19: Ninguno | S19: Ninguno | T19: Ninguno | V19: Análisis / Generación de código
A20: 46255 | B20: Sergio Galaz | C20: LT | D20: Ecosistemas | E20: Análisis | F20: GitHub Copilot CLI / VS Code | G20: Claude 3.5 Sonnet | H20: Alto | I20: No aplica | J20: Documentación técnica | K20: 110 | L20: 120 | M20: 540 | N20: Éxito | O20: 5 | P20: Sí | Q20: El uso de prompts planos en CLAUDE.md solo logra un ~80% de conformidad ante restricciones críticas. | R20: Para lograr un 100% de cumplimiento determinista, es obligatorio configurar ganchos mecánicos a nivel de sistema (PostToolUse y PreToolUse) para compilar el código en caliente y bloquear el flujo si la sintaxis falla. | S20: Degradación de rendimiento si las validaciones del hook post-guardado tardan más de 5 segundos. | T20: Implementar scripts de validación ultra-rápidos que solo analicen los archivos en estado "staged". | U20: Hooks, Copilot CLI, Automatización, Calidad, Inspiración-Gentle-AI | V20: Informes, Presentación, Uso de patrones
A21: 46255 | B21: Moises Lagos | C21: DEV | D21: App & Ecosistemas | E21: Análisis | F21: Google Antigravity | G21: Gemini pro 3.1 | H21: Alto | I21: No aplica | J21: Análisis de requerimientos | K21: 0 | L21: 80 | M21: 240 | N21: Éxito | O21: 5 | P21: No | T21: Ninguno | V21: Analisis de requerimientos
A22: 46255 | B22: Moises Lagos | C22: DEV | D22: App & Ecosistemas | E22: Desarrollo | F22: Google Antigravity | G22: Gemini pro 3.1 / Opus 4.6 | H22: Medio | I22: No aplica | J22: Generación de código | K22: 0 | L22: 40 | M22: 480 | N22: Parcial | O22: 3 | P22: Sí | Q22: Reporte UI en frontend, utilizando gráficos | R22: Gemini pro 3.1 no pudo ejecutar correctamente la UI, o formó bien le gráfico ni los estilos por sección. Opus 4.6 armó mejor la vista pero con un resultado parcial. Finalmente, se aplica vibecoding para terminar con la vista desarrollada correctamente. | S22: Opus 4.6 entregó un resultado más concreto, aunque parcial, el modelo opus demostró funcionar mejor en este caso. | T22: Calidad o precisión | U22: Asegurarse que al ejecutar desarrollos con antigravity, que use las skills de diseño, indicando su uso explícitamente para mejores resultados. | V22: Generación de código
A23: 46259 | B23: Sergio Galaz | C23: LT | D23: Ecosistemas | E23: Documentación | F23: Claude Code | G23: Claude Opus 4.5 | H23: Muy Alto | I23: No aplica (Se evaluó Engram MCP para inspiración pero se descartó su uso) | J23: Documentación técnica | K23: 150 | L23: 150 | M23: 600 | N23: Éxito | O23: 5 | P23: Sí | Q23: El desborde del contexto de tokens (*context rot*) provoca que el agente olvide las decisiones de diseño arquitectónico. | R23: Se estudió Engram MCP como inspiración para entender la estructuración de observaciones. Para evitar dependencias locales pesadas, no se implementó. Diseñamos una persistencia pura basada en Git, guardando planes en archivos Markdown (tasks.md, design.md). | S23: Amnesia técnica si las conversaciones se alargan sin un plan persistente en Markdown. | T23: Forzar al agente a documentar decisiones de diseño directamente en Git utilizando design.md y tasks.md para persistir el conocimiento. | U23: Orquestación, Planificación, Contexto, Git, Inspiración-Engram | V23: Informes, Presentación, Uso de patrones
A24: 46259 | B24: Sergio Galaz | C24: LT | D24: Ecosistemas | E24: Desarrollo | F24: Claude (chat web) | G24: Claude Opus 5 | H24: Muy Alto | I24: No aplica | J24: Documentación técnica | K24: 60 | L24: 45 | M24: 180 | N24: Éxito | O24: 5 | P24: Sí | Q24: El agente de arquitectura era genérico (fronteras controller/service/repository) y no distinguía los patrones propios de Angular. Además asumía contratos del backend sin evidencia, lo que llevaba a diseñar sobre suposiciones no validadas. | R24: Restringir las herramientas en el frontmatter convierte "no implementes código" de instrucción blanda en restricción estructural. Se formalizó el protocolo BQ-<n> en backend-questions.md con campos status, category, question, why y needed-detail, prohibiendo inferir forma de payloads, códigos de error, paginación o auth. Ninguna recomendación de diseño puede darse por final si depende de un BQ en estado open. | S24: Que el equipo responda un BQ de forma especulativa y se termine diseñando sobre una suposición igual de frágil que la original. | T24: Exigir que toda respuesta a un BQ se verifique contra el código real del repo backend antes de marcarla como answered. | U24: Agentes, Angular 20, NgRx Signal Store, Contrato API, Protocolo BQ | V24: Informes, Presentación, Uso de patrones
A25: 46259 | B25: Sergio Galaz | C25: LT | D25: Ecosistemas | E25: Análisis | F25: Claude (chat web) | G25: Claude Opus 5 | H25: Muy Alto | I25: No aplica | J25: Documentación técnica | K25: 55 | L25: 40 | M25: 240 | N25: Pivoteado | O25: 5 | P25: Sí | Q25: Se estaba diseñando un orquestador con agentes por fase (proposal, spec, design, verify, archive) que reimplementaba a mano lo que OpenSpec ya genera de forma nativa y conectada a la CLI real. | R25: openspec init con target github-copilot ya genera skills para todo el ciclo (new-change, continue-change, apply-change, verify-change, archive-change, explore, propose, ff-change, sync-specs, update-change, bulk-archive, onboard). La skill continue-change crea UN artefacto por invocación y se detiene esperando confirmación: eso YA es el gate humano, por lo que un orquestador con handoffs resultaba ceremonia redundante. Se descartó el enfoque de sdd-orchestrator diseñado ese mismo día. | S25: Mantener artefactos custom que dupliquen funcionalidad nativa y que diverjan en cada upgrade de la CLI de OpenSpec. | T25: Antes de crear cualquier agente o skill, auditar qué cubre OpenSpec de forma nativa y construir solo sobre los huecos reales comprobados. | U25: OpenSpec, Skills nativas, Simplificación, Anti-duplicación | V25: Informes, Presentación, Uso de patrones
A26: 46259 | B26: Sergio Galaz | C26: LT | D26: Ecosistemas | E26: Análisis | F26: Claude (chat web) | G26: Claude Opus 5 | H26: Muy Alto | I26: No aplica | J26: Documentación técnica | K26: 70 | L26: 50 | M26: 300 | N26: Éxito | O26: 5 | P26: Sí | Q26: openspec-apply-change no impone TDD: su instrucción literal es "make the code changes required", sin exigir RED antes de GREEN. openspec-verify-change es heurístico, basado en búsqueda de keywords en el código, y no ejecuta el test suite ni openspec validate --strict. La skill oficial angular-developer de Google no cubre NgRx Signal Store en absoluto. | R26: tdd-apply se implementó como custom agent y no como skill para que la invocación sea determinista (el dev lo elige del dropdown) y no compita con apply-change por auto-descubrimiento. strict-verify envuelve el reporte heurístico y le agrega evidencia real ejecutada. Ninguna task se marca completa sin RED confirmado y suite completa en verde. Se confirmó el stack de testing del frontend: Jasmine + Karma, con npm run test -- --watch=false obligatorio porque ng test corre en modo watch por defecto. | S26: Que el desarrollador use openspec-apply-change por comodidad en tasks "triviales" y se pierda la disciplina RED-GREEN justo donde menos se nota. | T26: Documentarlo como error común en la guía de desarrolladores y reforzarlo desde copilot-instructions.md, que se inyecta en todos los turnos de chat. | U26: TDD, Verificación, Custom agents, Huecos, Evidencia real | V26: Informes, Presentación, Uso de patrones
A27: 46259 | B27: Sergio Galaz | C27: LT | D27: Ecosistemas | E27: Desarrollo | F27: Claude (chat web) | G27: Claude Opus 5 | H27: Alto | I27: No aplica | J27: Documentación técnica | K27: 45 | L27: 35 | M27: 150 | N27: Éxito | O27: 5 | P27: Sí | Q27: Error de parseo "Implicit keys need to be on a single line" al escribir strings que contienen dos puntos seguidos de espacio dentro de bullets multilínea sin comillas en la sección rules. | R27: config.yaml tiene tres niveles con semántica distinta: context (global, se muestra al crear cualquier artefacto), rules (por artefacto) y operations (apply/archive). context y rules son constraints; operations.guidance es explícitamente advisory, no enforcement duro, y por eso la disciplina TDD real se fuerza desde el agente tdd-apply y no desde el config. En YAML, ": " abre un mapa: todo bullet multilínea debe usar bloque >- o ir entre comillas. | S27: Confiar en operations.guidance como si fuera enforcement determinista cuando la propia skill lo describe como consejo opcional. | T27: Validar todo YAML con un parser estricto antes de commitear, y documentar qué capas son constraint y cuáles advisory. | U27: OpenSpec, config.yaml, YAML, Enforcement, Contexto | V27: Informes, Presentación, Uso de patrones
A28: 46260 | B28: Moises Lagos | C28: DEV | D28: App & Ecosistemas | E28: Análisis | F28: GitHub Copilot Agent Skills | G28: GPT 5.6 Terra | H28: Medio | I28: No aplica | J28: Análisis de requerimientos | K28: 1599.6 créditos | L28: 480 | M28: 960 | N28: Éxito | O28: 5 | P28: No | Q28: Análisis procesamiento de carga notificaciones push | R28: Ninguno | S28: Copilot realizó el análsis y diseñó todo lo que se le solicitó, faltó especificar por parte de desarrollador para llegar con la solución completa. | T28: Ninguno | U28: Procurar ser lo más detallista posible en fase de exploración y especificación. | V28: Análisis / especificación de requerimientos
A29: 46260 | B29: Moises Lagos | C29: DEV | D29: App & Ecosistemas | E29: Desarrollo | F29: GitHub Copilot Agent Skills | G29: GPT 5.6 Terra | H29: Medio | I29: No aplica | J29: Generación de código | K29: 1066.4 créditos | L29: 480 | M29: 1440 | N29: Éxito | O29: 5 | P29: No | Q29: Desarrollo backend, procesamiento de carga notificaciones push | R29: Copilot generó todo lo que se le pidió, pero a raíz de las pruebas realizadas se evidenciaron requerimientos técnicos faltantes, por lo que se iteró constantemente para actualizar archivos design.md y task.md, luego aplicar los nuevos cambios. Fue un proceso iterativo. | S29: Se debe especificar al detalle para que copilot entregue todo lo necesario, evitar iteraciones para no demorar el desarrollo y gasto de créditos. | T29: Ninguno | U29: En caso de falta de especificación, utilizar comando update y continue para actualizar especificación necesaria para archivos md | V29: Generación de código
A30: 46261 | B30: Sergio Galaz | C30: LT | D30: App & Ecosistemas | E30: Documentación | F30: Claude (chat web) | G30: Claude Opus 5 | H30: Alto | I30: No aplica | J30: Documentación técnica | K30: 30 | L30: 25 | M30: 240 | N30: Éxito | O30: 5 | P30: Sí | Q30: El documento de arquitectura del frontend declaraba el envelope como ApiResponse<T> con la forma { code, data, message }, mientras que el estándar real del backend es ResponseData<T> con propiedad Data, más ResponseMeta para paginación y ResponseError generado por middleware. | R30: El protocolo de comunicación entre repos funciona en ambas direcciones: el frontend levanta BQ hacia el backend, y el backend debe marcar explícitamente los breaking changes hacia el frontend antes de archivar. Se confirmó ResponseData<T> como contrato oficial y se corrigió la documentación del frontend en config.yaml y copilot-instructions.md. | S30: RolesService en el frontend fue integrado asumiendo ApiResponse<T>, por lo que puede estar parseando mal la respuesta real o funcionando por coincidencia. | T30: Abrir un change de OpenSpec dedicado a auditar y corregir RolesService contra ResponseData<T>, con tests que verifiquen el parseo del envelope real. | U30: Contrato API, ResponseData, Frontend-Backend, Deuda técnica | V30: Informes, Presentación, Uso de patrones
A31: 46261 | B31: Sergio Galaz | C31: LT | D31: App & Ecosistemas | E31: Desarrollo | F31: Claude (chat web) | G31: Claude Opus 5 | H31: Muy Alto | I31: No aplica | J31: Documentación técnica | K31: 65 | L31: 45 | M31: 300 | N31: Éxito | O31: 4 | P31: Sí | Q31: El copilot-instructions.md del backend tenía un bloque de código sin cerrar que rompía el render, viñetas con doble guion no válidas en markdown, no mencionaba el flujo OpenSpec ni el framework de testing, y trataba TDD como sugerencia en vez de disciplina obligatoria. Además ni verify-change ni strict-verify revisaban calidad de código, solo completitud respecto a la spec. | R31: Ambos repos quedaron con estructura idéntica: 3 custom agents (architecture, tdd-apply, code-review), 3 skills (architecture-analysis, strict-verify, conventional-commits), config.yaml, copilot-instructions.md y guía de desarrolladores. code-review revisa el diff completo antes de Verify, cubriendo SOLID, Clean Code y performance. El strict-verify del backend incluye además un chequeo de impacto de contrato hacia el frontend antes de permitir el archivado. | S31: El framework de testing del backend (xUnit + Moq con dotnet test) quedó asumido y no confirmado; tdd-apply y strict-verify dependen de ese comando para producir evidencia real. | T31: Confirmar el stack de testing del backend y ajustar los cuatro archivos que lo referencian antes de usar el flujo en un change productivo. | U31: Backend, .NET 10, EF Core, Simetría, Code Review, Testing | V31: Informes, Presentación, Uso de patrones
A32: 46261 | B32: Sergio Galaz | C32: LT | D32: Ecosistemas | E32: Documentación | F32: Claude (chat web) | G32: Claude Opus 5 | H32: Muy Alto | I32: No aplica | J32: Documentación técnica | K32: 75 | L32: 55 | M32: 360 | N32: Éxito | O32: 5 | P32: Sí | Q32: El equipo no tiene commitlint ni husky, así que no hay validación automática de mensajes. Además el flujo original solo contemplaba commits de código: los artefactos de planificación y el archivado quedaban sin commitear, y el primer commit de task arrastraba todos los .md de planificación. | R32: La rama debe crearse ANTES del proposal, porque los artefactos de planificación se commitean. Hay cuatro momentos de commit: artefactos con docs(openspec), tasks con feat/fix, correcciones de review con fix, y archivado con docs(openspec), todos con footer Refs para trazabilidad contra el change. Una HU del cliente no equivale a un change: HU04-1 se descompuso en 6 changes independientemente verificables, y los CAs no se traducen uno a uno a requirements. | S32: Si los PR a dev se mergean con squash, todos los commits atómicos del ciclo TDD se colapsan en uno solo y únicamente sobrevive el título del PR, perdiendo gran parte de la trazabilidad. | T32: Definir formalmente la estrategia de merge del equipo (squash vs merge commit) y, si es squash, exigir que el título del PR siga Conventional Commits. | U32: Conventional Commits, Ramas, Trazabilidad, HU04-1, Descomposición | V32: Informes, Presentación, Uso de patrones
A33: 46262 | B33: Sergio Galaz | C33: LT | D33: App & Ecosistemas | E33: Otro | F33: Microsoft Copilot / GitHub Copilot Chat | G33: Automático | H33: Alto | I33: No aplica | J33: Documentación técnica | K33: 0 | L33: 180 | M33: 720 | N33: Pivoteado | O33: 5 | P33: Sí | Q33: La instalación global de la CLI y la ejecución de la extensión ESM (sdd-cli-extension.mjs) requieren Node.js v20.19.0+. Dos de las laptops de desarrollo tienen Node.js v14/v16 bloqueado por dependencias heredadas y restricciones corporativas. | R33: Diseñamos la estrategia Zero-CLI. Si el entorno físico local del programador está obsoleto, la IA puede emular las llamadas lógicas de la CLI ejecutando los archivos físicamente en disco mediante el agente. El proceso metodológico de specs y planes es más importante que el ejecutable físico. | S33: Pérdida de validación automática por eventos de sistema (compilación reactiva en caliente) al no contar con hooks nativos locales. | T33: El programador debe ordenar manualmente a la IA que ejecute un test suite de validación como comando de chat. | U33: Bloqueo, Entorno, Node.js, Zero-CLI, Emulación-IA | V33: Informes, Presentación, Uso de patrones
A34: 46265 | B34: Sergio Galaz | C34: LT | D34: Ecosistemas | E34: Documentación | F34: Claude Code | G34: Claude 3.5 Sonnet | H34: Alto | I34: No aplica | J34: Documentación técnica | K34: 95 | L34: 100 | M34: 400 | N34: Éxito | O34: 5 | P34: Sí | Q34: El agente emulador a veces olvidaba aplicar el algoritmo de fusión de delta specs al recibir un comando de archivado, generando desalineación en las carpetas principales. | R34: Escribir instrucciones de forma procedural y estructurada con un checklist de 5 pasos numerados para que la IA realice un escaneo secuencial de deltas (ADDED, MODIFIED, REMOVED) y actualice la spec principal en Git de forma inequívoca. | S34: Consumo moderado-alto de tokens al tener que cargar el manual completo de Zero-CLI en el system prompt. | T34: Configurar el archivo de instrucciones como una "Skill" local en el IDE para que se cargue bajo demanda. | U34: Zero-CLI, Instrucciones, Prompt Engineering, Git | V34: Informes, Presentación, Uso de patrones
A35: 46267 | B35: Sergio Galaz | C35: LT | D35: Ecosistemas | E35: Desarrollo | F35: GitHub Copilot Chat | G35: Claude 3.5 Sonnet | H35: Alto | I35: No aplica | J35: Documentación técnica | K35: 120 | L35: 120 | M35: 480 | N35: Éxito | O35: 5 | P35: Sí | Q35: Al programar componentes de Angular 20, los agentes mezclaban reactividad basada en RxJS de versiones antiguas con Signals modernos, o se olvidaban del tracking en el nuevo control de flujo @for. | R35: Crear archivos de instrucciones transversales con reglas duras: prohibición absoluta de *ngIf/*ngFor, uso obligatorio de computed() para derivaciones, bootstrap Zoneless explícito, y pruebas unitarias usando DeferBlockFixture para componentes diferidos con @defer. | S35: Que los desarrolladores olviden llamar a estas instrucciones en sus sesiones de chat con la IA. | T35: Configurar el frontmatter de los agentes de diseño e implementación para cargar de forma eager las directivas basándose en los patrones de extensión del archivo (applyTo: "src/**/*.ts"). | U35: Angular 20, Signals, Zoneless, Control de Flujo, Testing | V35: Informes, Presentación, Uso de patrones
A36: 46267 | B36: Dennisse Cannobbio | C36: DEV | D36: App & Ecosistemas | E36: Desarrollo | F36: GitHub Copilot Chat | G36: Automatico | H36: No aplica | I36: No aplica | J36: Generación de tests | L36: 60 | M36: - | N36: Fallido | O36: 2 | P36: Sí | Q36: Realizacion de un flujo de openspec: /verify, el cual verifica que se hayan cumplido los criterios y de paso, verifica que las TODAS las pruebas pasen. | R36: Estaba realizando el strict-verify para poder archivar un spec realizado. Copilot tiene la instruccion de que todos los tests deben pasar, habia un test fallido de una implementacion anterior (Antes de que se implementara la instruccion de todos los test deben estar en verde) y no lograba resolver el test fallido. En consecuencia se tuvo que pausar el desarrollo (para no seguir consumiendo tokens) y corregir el test manualmente | S36: No aplica | T36: Calidad o precisión | U36: Enfocarse solo en los tests implementados en el desarrollo. Ya que si necesita el contexto para resolver el otro test de otra implementacion, se desvia un poco de la spec. | V36: Pruebas unitarias, Desarrollo de Codigo
A37: 46269 | B37: Sergio Galaz | C37: LT | D37: Ecosistemas | E37: Desarrollo | F37: Claude Code | G37: Claude Opus 4.5 | H37: Muy Alto | I37: No aplica | J37: Documentación técnica | K37: 85 | L37: 90 | M37: 360 | N37: Éxito | O37: 5 | P37: Sí | Q37: El agente de arquitectura a veces intentaba escribir código de producción de forma errática en lugar de limitarse a proponer el diseño técnico, sobrecargando la ventana con código que no correspondía a su rol. | R37: El principio de "no implementar código" debe forzarse mediante barreras físicas de herramientas en el frontmatter del archivo del agente (disallowedTools: [write, edit, run_command]). De esta forma, el agente no puede escribir archivos por error técnico. | S37: Que el orquestador principal intente delegar tareas de desarrollo al arquitecto y se produce un fallo de ejecución de herramienta. | T37: Asegurar que el agente orquestador comprenda las limitaciones de herramientas del arquitecto antes de asignarle un ticket. | U37: Agentes, Arquitectura, Claude Opus, Seguridad, Frontmatter | V37: Informes, Presentación, Uso de patrones
A38: 46269 | B38: Jerson Pacheco | C38: PM | D38: App & Ecosistemas | E38: Análisis | F38: Microsoft Copilot | G38: Automatico | H38: No aplica | I38: No aplica | J38: Redacción de informes | K38: 0 | L38: 60 | M38: 300 | N38: Éxito | O38: 4 | P38: Sí | Q38: Revisión de ficha de iniciciativa de plan director, creación de pitch y adecuación para público objetivo | R38: Las anotaciones (Proyectos en Microsoft copilot) no permiten seleccionar el modelo a utilizar, al comparar el mismo prompt con un chat normal y seleccionar un modelo acorda al análisis el resultado es mejor. | S38: Analizar una ficha o presentación con el persona pattern permite identificar puntos debiles, contradicciones o plantear posibles preguntas desde distintas perspectiva y roles, lo que ayuda a preparar mejor la preentación. También el utilizar audience persona pattern permite adecuar pitch's que se vayan a realizar acorde al público objetivo. | T38: Ninguno | U38: Para depurar presentaciones utlizar persona pattern para su analisis y audience persona pattern para adaptar la presentación acorde al público | V38: Informes, Presentación, Uso de patrones
A39: 46272 | B39: Dennisse Cannobbio | C39: DEV | D39: App & Ecosistemas | E39: Análisis | F39: Claude Code | G39: Claude Opus 5, plan Pro. | H39: No aplica | I39: No aplica | J39: Análisis de requerimientos | K39: 50 % de la sesion | L39: 150 | M39: 210 | N39: Éxito | O39: 5 | P39: Si | Q39: Analisis de requerimientos para desarrollo de HU de validacion al subir una audiencia en el paso 3 del formulario de notificacion (Backoffice Notificaciones) | R39: No se encontraron problemas | S39: No aplica | T39: Ninguno | U39: Ninguno | V39: Analisis de requerimientos
A40: 46272 | B40: Dennisse Cannobbio | C40: DEV | D40: App & Ecosistemas | E40: Desarrollo | F40: Claude Code | G40: Claude Sonnet 5, plan Pro. | H40: No aplica | I40: No aplica | J40: Generación de código | K40: 100% de la sesion | L40: 120 | M40: 210 | N40: Éxito | O40: 5 | P40: Sí | Q40: Ejecucion del desarrollo de HU de validacion al subir una audiencia en el paso 3 del formulario de notificacion (Backoffice Notificaciones) | R40: No se encontraron problemas | S40: No aplica | T40: Ninguno | U40: Ninguno | V40: Desarrollo
...

Sheet Resumen
A1: Resumen de adopción de IA del equipo
A2: Se actualiza solo. No editar celdas con fórmula.
A4: Totales generales
A5: Total de registros | B5: =COUNTA('Registro Diario'!B19:B518) -> 67
A6: Tiempo total invertido (min) | B6: =SUM('Registro Diario'!L19:L518) -> 4209
A7: Tiempo total ahorrado estimado (min) | B7: =SUM('Registro Diario'!M19:M518) -> 14445
A8: Confianza promedio (1-5) | B8: =IFERROR(AVERAGE('Registro Diario'!O19:O518),0) -> 4.7384615
A9: % con validación humana requerida | B9: =IFERROR(COUNTIF('Registro Diario'!P19:P518,"Sí")/COUNTA('Registro Diario'!P19:P518),0) -> 0.56923077
A11: Por resultado
A12: Éxito | B12: =COUNTIF('Registro Diario'!N19:N518,"Éxito") -> 56
A13: Parcial | B13: =COUNTIF('Registro Diario'!N19:N518,"Parcial") -> 5
A14: Fallido | B14: =COUNTIF('Registro Diario'!N19:N518,"Fallido") -> 2
A16: Por herramienta
A17: GitHub Copilot Chat | B17: =COUNTIF('Registro Diario'!F19:F518,"GitHub Copilot Chat") -> 6
A18: GitHub Copilot Autocompletado | B18: =COUNTIF('Registro Diario'!F19:F518,"GitHub Copilot Autocompletado") -> 0
A19: GitHub Copilot Agent Skills | B19: =COUNTIF('Registro Diario'!F19:F518,"GitHub Copilot Agent Skills") -> 26
A20: Microsoft Copilot | B20: =COUNTIF('Registro Diario'!F19:F518,"Microsoft Copilot") -> 3
A21: Google Antigravity | B21: =COUNTIF('Registro Diario'!F19:F518,"Google Antigravity") -> 11
A22: ChatGPT Codex | B22: =COUNTIF('Registro Diario'!F19:F518,"ChatGPT Codex") -> 0
A23: Claude Code | B23: =COUNTIF('Registro Diario'!F19:F518,"Claude Code") -> 11
A24: Claude Cowork | B24: =COUNTIF('Registro Diario'!F19:F518,"Claude Cowork") -> 0
A25: Postbot (Postman AI) | B25: =COUNTIF('Registro Diario'!F19:F518,"Postbot (Postman AI)") -> 0
A26: Otro | B26: =COUNTIF('Registro Diario'!F19:F518,"Otro") -> 0
A28: Por nivel de razonamiento
A29: No aplica | B29: =COUNTIF('Registro Diario'!H19:H518,"No aplica") -> 8
A30: Bajo | B30: =COUNTIF('Registro Diario'!H19:H518,"Bajo") -> 5
A31: Medio | B31: =COUNTIF('Registro Diario'!H19:H518,"Medio") -> 15
A32: Alto | B32: =COUNTIF('Registro Diario'!H19:H518,"Alto") -> 32
A33: Extendido | B33: =COUNTIF('Registro Diario'!H19:H518,"Extendido") -> 0
A35: Por tipo de uso
A36: Generación de código | B36: =COUNTIF('Registro Diario'!J19:J518,"Generación de código") -> 19
A37: Refactor | B37: =COUNTIF('Registro Diario'!J19:J518,"Refactor") -> 3
A38: Debugging | B38: =COUNTIF('Registro Diario'!J19:J518,"Debugging") -> 0
A39: Generación de tests | B39: =COUNTIF('Registro Diario'!J19:J518,"Generación de tests") -> 2
A40: Documentación técnica | B40: =COUNTIF('Registro Diario'!J19:J518,"Documentación técnica") -> 23
A41: Análisis de requerimientos | B41: =COUNTIF('Registro Diario'!J19:J518,"Análisis de requerimientos") -> 18
A42: Redacción de informes | B42: =COUNTIF('Registro Diario'!J19:J518,"Redacción de informes") -> 1
A43: Revisión de código | B43: =COUNTIF('Registro Diario'!J19:J518,"Revisión de código") -> 0
A44: Otro | B44: =COUNTIF('Registro Diario'!J19:J518,"Otro") -> 1
A46: Por riesgo identificado
...

Sheet Instructivo
A1: Cómo usar este registro
A2: Objetivo: dejar trazabilidad diaria del uso de IA en tareas de desarrollo, análisis, documentación e informes, como insumo para el piloto de adopción de IA del equipo (fase piloto de bajo riesgo → escalamiento → gobernanza).
A6: Campo | B6: Qué registrar
A7: Fecha | B7: Día en que se realizó la tarea (no el día en que se llena la planilla, si son distintos).
A8: Colaborador | B8: Nombre de quien registra (lista desplegable con el equipo).
A9: Rol | B9: PM, LT (Líder Técnico) o DEV.
A10: Equipo | B10: App & Ecosistemas, App móvil, o Ecosistemas.
A11: Tarea / Contexto | B11: Naturaleza de la actividad: Desarrollo, Análisis, Documentación, Informes, Testing/QA, Otro.
A12: Herramienta IA | B12: Qué herramienta del stack autorizado se usó.
A13: Modelo | B13: Opcional. Modelo específico usado dentro de la herramienta, si se conoce (ej: Claude Sonnet 4.5, GPT-5, Gemini 3 Pro). Texto libre — no es dropdown porque los modelos cambian seguido. Dejar vacío si no se sabe o no aplica.
A14: Nivel de razonamiento | B14: Opcional. Nivel de 'thinking' / reasoning effort usado, si la herramienta lo permite elegir (ej: extended thinking en Claude, reasoning effort en modelos o-series). Marcar 'No aplica' si la herramienta no expone esa opción.
A15: Tipo de uso | B15: Qué se hizo específicamente con la IA (generar código, redactar informe, etc.).
A16: Tiempo invertido (min) | B16: Minutos dedicados a interactuar con la IA para esa tarea (prompting, revisión, ajustes).
A17: Tiempo estimado ahorrado (min) | B17: Estimación honesta del tiempo que se habría tomado sin IA, menos el tiempo invertido.
... A27: MCP | B27: Campo abierto. Servidor/es MCP (Model Context Protocol) utilizado/s en la tarea, si aplica (ej: MCP de Jira, GitHub, filesystem, base de datos). Dejar vacío si no se usó ningún MCP.
A29: Ejemplo de fila completa
A30: Campo | B30: Valor de ejemplo
A31: Fecha | B31: 04-09-2026
A32: Colaborador | B32: Jerson Pacheco
A33: Rol | B33: PM
A34: Equipo | B34: App móvil
A35: Tarea / Contexto | B35: Documentación
A36: Herramienta IA | B36: GitHub Copilot Chat
A37: Modelo | B37: Claude Sonnet 4.5
A38: Nivel de razonamiento | B38: Medio
A39: Tipo de uso | B39: Documentación técnica
A40: Tiempo invertido (min) | B40: 20
A41: Tiempo estimado ahorrado (min) | B41: 45
A42: Resultado | B42: Éxito
A43: Confianza en el output (1-5) | B43: 4
A44: ¿Requirió validación humana? | B44: Sí
A45: Problemas encontrados | B45: Contexto insuficiente en el primer intento, mejoró al pasarle el código completo
A46: Aprendizajes / Insights | B46: Pegar el archivo completo (no solo el fragmento) mejora mucho la calidad del resultado
A47: Riesgo identificado | B47: Ninguno
A48: Sugerencias de mejora | B48: Estandarizar un prompt base para documentación de endpoints
A49: Etiquetas | B49: documentación, prompt-engineering
A50: Tokens consumidos | B50: 12500
A51: MCP | B51: MCP Jira, MCP GitHub
A53: Nota: esta fila de ejemplo es solo referencia. No la copies en la hoja 'Registro Diario'.
